Workbook

Sheet Vigiles R
A1: Psaume | B1: Versets
A2: 7 | B2: 2-10
A3: 7 | B3: 11-18
A4: 16 | B4: 1-7
A5: 16 | B5: 8-15
A6: 17 | B6: 2-11
A7: 17 | B7: 12-20
A8: 17 | B8: 21-30
A9: 17 | B9: 31-35
A10: 17 | B10: 36-46
A11: 17 | B11: 47-51
A12: 21 | B12: 2-11
A13: 21 | B13: 12-22
... A124: 144 | B124: 13b-21
A125: 9A | B125: 2-13
A126: 9A | B126: 14-21
A127: 9B | B127: 1-11
A128: 9B | B128: 12-18

Sheet Laudes R
C2: Laudes
C3: I | D3: II | E3: III | F3: IV
B4: Dimanche | C4: 62 | D4: 117 | E4: 92 | F4: 117
C5: AT 49 | D5: AT 48 | E5: AT 49 | F5: AT 48
C6: 149 | D6: 150 | E6: 148 | F6: 150
B7: Lundi | C7: 5 | D7: 41 | E7: 83 | F7: 89
C8: AT 4 | D8: AT 15 | E8: AT 17 | F8: AT 27
C9: 28 | D9: 18A | E9: 95 | F9: 134
B10: Mardi | C10: 23 | D10: 42 | E10: 84 | F10: 100
C11: AT 6 | D11: AT 25 | E11: AT 21 | F11: AT 47
C12: 32 | D12: 64 | E12: 66 | F12: 143
B13: Mercredi | C13: 35 | D13: 76 | E13: 85 | F13: 107
C14: AT 8 | D14: AT 3 | E14: AT 23 | F14: AT 38
C15: 46 | D15: 96 | E15: 97 | F15: 145
B16: Jeudi | C16: 56 | D16: 79 | E16: 86 | F16: 142
C17: AT 44 | D17: AT 20 | E17: AT 26 | F17: AT 41
C18: 47 | D18: 80 | E18: 98 | F18: 146
B19: Vendredi | C19: 50 | D19: 50 | E19: 50 | F19: 50
C20: AT 30 | D20: AT 57 | E20: AT 42 | F20: AT 7
C21: 99 | D21: 147 | E21: 99 | F21: 147
B22: Samedi | C22: 118 XIX | D22: 91 | E22: 118, XIX | F22: 91
C23: AT 1 | D23: AT 2 | E23: AT 12 | F23: AT 46
C24: 116 | D24: 8 | E24: 116 | F24: 8

Sheet MdJ R
C2: Milieu du Jour
C3: I | E3: II | G3: III | I3: IV
B4: Dimanche
B7: Lundi
B10: Mardi
B13: Mercredi
B16: Jeudi
B19: Vendredi
B22: Samedi

Sheet Vêpres R
C2: Vêpres
C3: I | E3: II | G3: III | I3: IV
B4: Samedi
B7: Dimanche
B10: Lundi
B13: Mardi
B16: Mercredi | C16: 26 | D16: 1-6
C17: 26 | D17: 7-14
C18: 44 | D18: 2-10
B19: Jeudi | C19: 44 | D19: 11-18
C21: 48 | D21: 2-13
B22: Vendredi | C22: 48 | D22: 14-21
C27: 71 | D27: 1-11
C28: 71 | D28: 12-19
C29: 131 | D29: 1-10
C30: 131 | D30: 11-18
C32: 134 | D32: 1-12
C33: 134 | D33: 13-21
C34: 135 | D34: 1-9
C35: 135 | D35: 10-26
C40: 138 | D40: 1-10
C41: 138 | D41: 11-24
C43: 143 | D43: 1-8
C44: 143 | D44: 9-15
... C47: 144 | D47: 13b-21

Sheet Comp R
C2: Complies | D2: Complies
B4: Dimanche | C4: 90
B7: Lundi | C7: 85
B10: Mardi | C10: 142
B13: Mercredi | C13: 30 | D13: 2-9
C14: 129
B16: Jeudi | C16: 15
B19: Vendredi | C19: 87
B22: Samedi | C22: 4
C23: 133

Sheet TO R
B1: Laudes | F1: Vêpres | G1: Vêpres | H1: Vêpres | I1: Vêpres | J1: Vêpres | K1: Vêpres | L1: Vêpres | M1: Vêpres | N1: Vigiles | O1: Vigiles | P1: Vigiles | Q1: Vigiles | R1: Vigiles | S1: Vigiles | T1: Vigiles | U1: Vigiles | V1: Milieu du Jour | W1: Milieu du Jour | X1: Milieu du Jour | Y1: Milieu du Jour | Z1: Milieu du Jour | AA1: Milieu du Jour | AB1: Milieu du Jour | AC1: Milieu du Jour | AD1: Complies | AE1: Complies
B2: I | C2: II | D2: III | E2: IV | F2: I | H2: II | J2: III | L2: IV | N2: I | P2: II | R2: III | T2: IV | V2: I | X2: II | Z2: III | AB2: IV
A3: Dimanche | B3: 62 | C3: 117 | D3: 92 | E3: 117 | F3: 144 | G3: 1-13a | H3: 109 | J3: 109 | L3: 109 | N3: 1 | P3: 103 | Q3: 1-12 | R3: 144 | S3: 1-9 | T3: 23 | V3: 117 | W3: 1-4 | X3: 22 | Z3: 117 | AA3: 1-4 | AB3: 22 | AD3: 90
B4: AT 49 | C4: AT 48 | D4: AT 49 | E4: AT 48 | F4: 144 | G4: 13b-21 | H4: 113B | J4: 110 | L4: 111 | N4: 2 | P4: 103 | Q4: 13-23 | R4: 144 | S4: 10-14 | T4: 65 | U4: 1-12 | V4: 117 | W4: 5-24 | X4: 75 | Y4: 2-7 | Z4: 117 | AA4: 5-24 | AB4: 75 | AC4: 2-7
B5: 149 | C5: 150 | D5: 148 | E5: 150 | F5: NT VII | H5: NT XIV | J5: NT XIV | L5: NT XIV | N5: 3 | P5: 103 | Q5: 24-35 | R5: 144 | S5: 15-21 | T5: 65 | U5: 13-20 | V5: 117 | W5: 25-29 | X5: 75 | Y5: 8-13 | Z5: 117 | AA5: 25-29 | AB5: 75 | AC5: 8-13
A6: Lundi | B6: 5 | C6: 41 | D6: 83 | E6: 89 | F6: 109 | H6: 44 | I6: 2-10 | J6: 122 | L6: 135 | M6: 1-9 | N6: 6 | P6: 30 | Q6: 2-9 | R6: 49 | S6: 1-6 | T6: 72 | U6: 1-12 | V6: 18B | X6: 118 - VI | Z6: 118 - XII | AB6: 118 - XVII | AD6: 85
B7: AT 4 | C7: AT 15 | D7: AT 17 | E7: AT 27 | F7: 110 | H7: 44 | I7: 11-18 | J7: 123 | L7: 135 | M7: 10-26 | N7: 9A | O7: 2-13 | P7: 30 | Q7: 10-19 | R7: 49 | S7: 7-15 | T7: 72 | U7: 13-20 | V7: 7 | W7: 2-10 | X7: 39 | Y7: 2-9 | Z7: 70 | AA7: 1-13 | AB7: 81
B8: 28 | C8: 18A | D8: 95 | E8: 134 | F8: NT XIV | H8: NT VI | J8: NT VI | L8: NT VI | N8: 9A | O8: 14-21 | P8: 30 | Q8: 20-25 | R8: 49 | S8: 16-23 | T8: 72 | U8: 21-28 | V8: 7 | W8: 11-18 | X8: 39 | Y8: 10-18 | Z8: 70 | AA8: 14-24 | AB8: 119
A9: Mardi | B9: 23 | C9: 42 | D9: 84 | E9: 100 | F9: 16 | H9: 48 | I9: 2-13 | J9: 124 | L9: 136 | N9: 9B | O9: 1-11 | P9: 36 | Q9: 1-11 | R9: 67 | S9: 2-11 | T9: 101 | U9: 2-12 | V9: 118 - I | X9: 118 - VII | Z9: 118 - XIII | AB9: 118 - XVIII | AD9: 142
B10: AT 6 | C10: AT 25 | D10: AT 21 | E10: AT 47 | F10: 16 | H10: 48 | I10: 14-21 | J10: 130 | L10: 137 | N10: 9B | O10: 12-18 | P10: 36 | Q10: 12-29 | R10: 67 | S10: 12-24 | T10: 101 | U10: 13-23 | V10: 12 | X10: 52 | Z10: 73 | AA10: 1-9 | AB10: 87 | AC10: 2-10a
B11: 32 | C11: 64 | D11: 66 | E11: 143 | F11: NT VI | H11: NT XI | J11: NT XI | L11: NT XI | N11: 11 | P11: 36 | Q11: 30-40 | R11: 67 | S11: 25-36 | T11: 101 | U11: 24-29 | V11: 13 | X11: 53 | Z11: 73 | AA11: 10-23 | AB11: 87 | AC11: 10b-19
A12: Mercredi | B12: 35 | C12: 76 | D12: 85 | E12: 107 | F12: 19 | H12: 61 | J12: 125 | L12: 138 | M12: 1-10 | N12: 17 | O12: 2-11 | P12: 38 | Q12: 2-7 | R12: 88 | S12: 2-19 | T12: 102 | U12: 1-7 | V12: 118 -II | X12: 118 - VIII | Z12: 118 - XIV | AB12: 118 - XIX | AD12: 30 | AE12: 2-9
B13: AT 8 | C13: AT 3 | D13: AT 23 | E13: AT 38 | F13: 20 | H13: 66 | J13: 126 | L13: 138 | M13: 11-24 | N13: 17 | O13: 12-20 | P13: 38 | Q13: 8-14 | R13: 88 | S13: 20-30 | T13: 102 | U13: 8-16 | V13: 16 | W13: 1-7 | X13: 54 | Y13: 2-16 | Z13: 69 | AB13: 93 | AC13: 1-11 | AD13: 129
B14: 46 | C14: 96 | D14: 97 | E14: 145 | F14: NT XI | H14: NT VIII | J14: NT VIII | L14: NT VIII | N14: 17 | O14: 21-30 | P14: 51 | R14: 88 | S14: 31-38 | T14: 102 | U14: 17-22 | V14: 16 | W14: 8-15 | X14: 54 | Y14: 17-24 | Z14: 74 | AB14: 93 | AC14: 12-23
A15: Jeudi | B15: 56 | C15: 79 | D15: 86 | E15: 142 | F15: 24 | H15: 71 | I15: 1-11 | J15: 131 | K15: 1-10 | L15: 143 | M15: 1-8 | N15: 17 | O15: 31-35 | P15: 43 | Q15: 2-9 | R15: 88 | S15: (20-22)+39-46 | T15: 43 | U15: 2-9 | V15: 118 - III | X15: 118 -IX | Z15: 118 - XV | AB15: 118 - XX | AD15: 15
B16: AT 44 | C16: AT 20 | D16: AT 26 | E16: AT 41 | F16: 24 | H16: 71 | I16: 12-19 | J16: 131 | K16: 11-18 | L16: 143 | M16: 9-15 | N16: 17 | O16: 36-46 | P16: 43 | Q16: 10-17 | R16: 88 | S16: 47-53 | T16: 43 | U16: 10-17 | V16: 24 | W16: 1-7 | X16: 55 | Z16: 78 | AB16: 127
B17: 47 | C17: 80 | D17: 98 | E17: 146 | F17: NT VIII | H17: NT XII | J17: NT XII | L17: NT XII | N17: 17 | O17: 47-51 | P17: 43 | Q17: 18-27 | R17: 89 | T17: 43 | U17: 18-27 | V17: 24 | W17: 8-14 | X17: 56 | Z17: 79 | AB17: 128
A18: Vendredi | B18: 50 | C18: 50 | D18: 50 | E18: 50 | F18: 26 | H18: 114 | J18: 134 | K18: 1-12 | N18: 34 | O18: 1-10 | P18: 37 | Q18: 2-8 | R18: 68 | S18: 2-13 | T18: 54 | U18: 2-10 | V18: 118 - IV | X18: 118 - X | Z18: 21 | AA18: 2-11 | AB18: 118 - XXI | AD18: 87
B19: AT 30 | C19: AT 57 | D19: AT 42 | E19: AT 7 | F19: 26 | H19: 120 | J19: 134 | K19: 13-21 | N19: 34 | O19: 11-16 | P19: 37 | Q19: 9-13 | R19: 68 | S19: 14-29 | T19: 54 | U19: 11-16 | V19: 25 | X19: 58 | Z19: 21 | AA19: 12-22 | AB19: 132
B20: 99 | C20: 147 | D20: 99 | E20: 147 | F20: NT XII | H20: NT XIII | J20: NT XIII | L20: NT XIII | N20: 34 | O20: 17-28 | P20: 37 | Q20: 14-23 | R20: 68 | S20: 30-37 | T20: 54 | U20: 17-24 | V20: 27 | X20: 59 | Z20: 21 | AA20: 23-32 | AB20: 139
A21: Samedi | B21: 118 XIX | C21: 91 | D21: 118, XIX | E21: 91 | F21: 31 | H21: 112 | J21: 121 | N21: 130 | P21: 135 | Q21: 1-9 | R21: 106 | S21: 1-16 | T21: 49 | U21: 1-6 | V21: 118 - V | X21: 118 - XI | Z21: 118 - XVI | AB21: 118 - XXII | AD21: 4
B22: AT 1 | C22: AT 2 | D22: AT 12 | E22: AT 46 | F22: 40 | H22: 115 | J22: 129 | N22: 131 | O22: 1-10 | P22: 135 | Q22: 10-15 | R22: 106 | S22: 17-32 | T22: 49 | U22: 7-15 | V22: 33 | W22: 2-11 | X22: 60 | Z22: 33 | AA22: 2-11 | AB22: 44 | AC22: 2-10 | AD22: 133
B23: 116 | C23: 8 | D23: 116 | E23: 8 | F23: NT VII | H23: NT VII | J23: NT VII | L23: NT VII | N23: 131 | O23: 11-18 | P23: 135 | Q23: 16-26 | R23: 106 | S23: 33-43 | T23: 49 | U23: 16-23 | V23: 33 | W23: 12-23 | X23: 63 | Z23: 33 | AA23: 12-23 | AB23: 44 | AC23: 11-18

Sheet TO G
B1: Laudes | F1: Vêpres | G1: Vêpres | H1: Vêpres | I1: Vêpres | J1: Vêpres | K1: Vêpres | L1: Vêpres | M1: Vêpres | N1: Vigiles | O1: Vigiles | P1: Vigiles | Q1: Vigiles | R1: Vigiles | S1: Vigiles | T1: Vigiles | U1: Vigiles | V1: Milieu du Jour | W1: Milieu du Jour | X1: Milieu du Jour | Y1: Milieu du Jour | Z1: Milieu du Jour | AA1: Milieu du Jour | AB1: Milieu du Jour | AC1: Milieu du Jour | AD1: Complies
B2: I | C2: II | D2: III | E2: IV | F2: I | H2: II | J2: III | L2: IV | N2: I | O2: V | P2: II | Q2: VI | R2: III | S2: VII | T2: IV | U2: VIII | V2: I | X2: II | Z2: III | AB2: IV
A3: Dimanche | B3: 92 | C3: 117 | D3: 92 | E3: 117 | F3: 109 | H3: 109 | J3: 109 | L3: 109 | N3: 1 | O3: 65 | P3: 12 | Q3: 67 | R3: 17 | S3: 88 | T3: 29 | U3: 103 | V3: 117 | W3: 1-4 | X3: 22 | Z3: 117 | AA3: 1-4 | AB3: 22 | AD3: 90
B4: AT 49 | C4: AT 48 | D4: AT 49 | E4: AT 48 | F4: 110 | H4: 112 | J4: 113A | L4: 114 | N4: 2 | O4: 75 | P4: 15 | Q4: 67 | R4: 17 | S4: 88 | T4: 49 | U4: 103 | V4: 117 | W4: 5-24 | X4: 75 | Y4: 2-7 | Z4: 117 | AA4: 5-24 | AB4: 75 | AC4: 2-7
B5: 148 | C5: 150 | D5: 148 | E5: 150 | F5: NT XIV | H5: NT XIV | J5: NT XIV | L5: NT XIV | N5: 3 | O5: 75 | P5: 23 | Q5: 67 | R5: 17 | S5: 88 | T5: 49 | U5: 103 | V5: 117 | W5: 25-29 | X5: 75 | Y5: 8-13 | Z5: 117 | AA5: 25-29 | AB5: 75 | AC5: 8-13
A6: Lundi | B6: 5 | C6: 35 | D6: 64 | E6: 84 | F6: 16 | H6: 71 | J6: 113B | L6: 136 | N6: 6 | P6: 34 | R6: 68 | T6: 102 | V6: 18B | X6: 118 - VI | Z6: 118 - XI | AB6: 118 - XVII | AD6: 4
B7: AT 4 | C7: AT 15 | D7: AT 17 | E7: AT 27 | F7: 16 | H7: 71 | J7: 115 | L7: 137 | N7: 9A | P7: 34 | R7: 68 | T7: 102 | V7: 7 | W7: 2-10 | X7: 39 | Y7: 2-9 | Z7: 70 | AA7: 1-13 | AB7: 81 | AD7: 133
B8: 91 | C8: 112-116 | D8: 91 | E8: 112-116 | F8: NT VI | H8: NT VI | J8: NT VI | L8: NT VI | N8: 9A | P8: 34 | R8: 68 | T8: 102 | V8: 7 | W8: 11-18 | X8: 39 | Y8: 10-18 | Z8: 70 | AA8: 14-24 | AB8: 119
A9: Mardi | B9: 8 | C9: 45 | D9: 66 | E9: 85 | F9: 19 | H9: 76 | J9: 126 | L9: 138 | N9: 9B | P9: 36 | R9: 72 | T9: 103 | U9: 1 | V9: 118 - I | X9: 118 - VII | Z9: 118 - XII | AB9: 118 - XVIII | AD9: 90
B10: AT 6 | C10: AT 25 | D10: AT 21 | E10: AT 47 | F10: 20 | H10: 76 | J10: 127 | L10: 138 | N10: 9B | P10: 36 | R10: 72 | T10: 103 | U10: 2 | V10: 11 | X10: 48 | Z10: 73 | AA10: 1-9 | AB10: 87 | AC10: 2-10a
B11: 95 | C11: 134 | D11: 95 | E11: 134 | F11: NT XI | H11: NT XI | J11: NT XI | L11: NT XI | N11: 10 | P11: 36 | R11: 72 | T11: 103 | U11: 3 | V11: 12 | X11: 48 | Z11: 73 | AA11: 10-23 | AB11: 87 | AC11: 10b-19
A12: Mercredi | B12: 18A | C12: 46 | D12: 69 | E12: 86 | F12: 24 | H12: 111 | J12: 130 | L12: 139 | N12: 15 | O12: 17 | P12: 37 | R12: 77 | T12: 104 | V12: 118 - II | X12: 118 - I | Z12: 118 - XIII | AB12: 118 - XIX | AD12: 4
B13: AT 8 | C13: AT 3 | D13: AT 23 | E13: AT 38 | F13: 24 | H13: 119 | J13: 132 | L13: 140 | N13: 23 | O13: 17 | P13: 37 | R13: 77 | T13: 104 | V13: 13 | X13: 52 | Z13: 74 | AB13: 93 | AC13: 1-11 | AD13: 133
B14: 96 | C14: 145 | D14: 96 | E14: 145 | F14: NT VIII | H14: NT VIII | J14: NT VIII | L14: NT VIII | N14: 65 | O14: 17 | P14: 38 | R14: 77 | T14: 104 | V14: 14 | X14: 53 | Z14: 76 | AB14: 93 | AC14: 12-23
A15: Jeudi | B15: 28 | C15: 47 | D15: 79 | E15: 89 | F15: 26 | H15: 120 | J15: 131 | K15: 1-10 | L15: 143 | N15: 67 | O15: 17 | P15: 43 | R15: 77 | T15: 105 | V15: 118 - III | X15: 118 - VIII | Z15: 118 - XIV | AB15: 118 - XX | AD15: 90
B16: AT 44 | C16: AT 20 | D16: AT 26 | E16: AT 41 | F16: 26 | H16: 122 | J16: 131 | K16: 11-18 | L16: 143 | N16: 67 | O16: 17 | P16: 43 | R16: 77 | T16: 105 | V16: 41 | X16: 54 | Z16: 80 | AB16: 127
B17: 97 | C17: 146 | D17: 97 | E17: 146 | F17: NT XII | H17: NT XII | J17: NT XII | L17: NT XII | N17: 67 | O17: 17 | P17: 43 | R17: 77 | T17: 105 | V17: 42 | X17: 54 | Z17: 80 | AB17: 128
A18: Vendredi | B18: 50 | C18: 50 | D18: 50 | E18: 50 | F18: 31 | H18: 123 | J18: 128 | L18: 141 | N18: 19 | Q18: 49 | R18: 78 | T18: 106 | V18: 118 - IV | X18: 118 - IX | Z18: 21 | AA18: 2-11 | AB18: 118 - XXI | AD18: 4
B19: AT 30 | C19: AT 57 | D19: AT 42 | E19: AT 7 | F19: 40 | H19: 124 | J19: 129 | L19: 142 | N19: 20 | P19: 51 | Q19: 51 | R19: 82 | T19: 106 | V19: 25 | X19: 55 | Z19: 21 | AA19: 12-22 | AB19: 132 | AD19: 133
B20: 98 | C20: 147 | D20: 98 | E20: 147 | F20: NT XIII | H20: NT XIII | J20: NT XIII | L20: NT XIII | N20: 29 | P20: 57 | Q20: 57 | R20: 100 | T20: 106 | V20: 27 | X20: 60 | Z20: 21 | AA20: 23-32 | AB20: 137
A21: Samedi | B21: 32 | C21: 56 | D21: 83 | E21: 107 | F21: 44 | G21: 2-10 | H21: 121 | J21: 135 | L21: 144 | N21: 30 | P21: 58 | R21: 101 | T21: 108 | V21: 118 - V | X21: 118 - X | Z21: 118 - XV | AB21: 118 - XXII | AD21: 4
B22: AT 1 | C22: AT 2 | D22: AT 12 | E22: AT 46 | F22: 44 | G22: 11-18 | H22: 125 | J22: 135 | L22: 144 | N22: 30 | P22: 58 | R22: 101 | T22: 108 | V22: 33 | W22: 2-11 | X22: 61 | Z22: 33 | AA22: 2-11 | AB22: 44 | AC22: 2-10 | AD22: 133
B23: 99 | C23: 149 | D23: 99 | E23: 149 | F23: NT VII | H23: NT VII | J23: NT VII | L23: NT VII | N23: 30 | P23: 59 | R23: 101 | T23: 108 | V23: 33 | W23: 12-23 | X23: 63 | Z23: 33 | AA23: 12-23 | AB23: 44 | AC23: 11-18
E26: 62

Sheet TO G Vig+MDJ
B1: Vigiles | C1: Vigiles | D1: Vigiles | E1: Vigiles | F1: Vigiles | G1: Vigiles | H1: Vigiles | I1: Vigiles | J1: Milieu du Jour | K1: Milieu du Jour | L1: Milieu du Jour | M1: Milieu du Jour | N1: Milieu du Jour | O1: Milieu du Jour | P1: Milieu du Jour | Q1: Milieu du Jour
B2: I | C2: V | D2: II | E2: VI | F2: III | G2: VII | H2: IV | I2: VIII | J2: I | L2: II | N2: III | P2: IV
A3: Dimanche | B3: 1 | C3: 65 | D3: 12 | E3: 67 | F3: 17 | G3: 88 | H3: 29 | I3: 103 | J3: 117 | K3: 1-4 | L3: 22 | N3: 117 | O3: 1-4 | P3: 22
B4: 2 | C4: 75 | D4: 15 | E4: 67 | F4: 17 | G4: 88 | H4: 49 | I4: 103 | J4: 117 | K4: 5-24 | L4: 75 | M4: 2-7 | N4: 117 | O4: 5-24 | P4: 75 | Q4: 2-7
B5: 3 | C5: 75 | D5: 23 | E5: 67 | F5: 17 | G5: 88 | H5: 49 | I5: 103 | J5: 117 | K5: 25-29 | L5: 75 | M5: 8-13 | N5: 117 | O5: 25-29 | P5: 75 | Q5: 8-13
A6: Lundi | B6: 6 | D6: 34 | F6: 68 | H6: 102 | J6: 18B | L6: 118 - VI | N6: 118 - XI | P6: 118 - XVII
B7: 9A | D7: 34 | F7: 68 | H7: 102 | J7: 7 | K7: 2-10 | L7: 39 | M7: 2-9 | N7: 70 | O7: 1-13 | P7: 81
B8: 9A | D8: 34 | F8: 68 | H8: 102 | J8: 7 | K8: 11-18 | L8: 39 | M8: 10-18 | N8: 70 | O8: 14-24 | P8: 119
A9: Mardi | B9: 9B | D9: 36 | F9: 72 | H9: 103 | I9: 1 | J9: 118 - I | L9: 118 - VII | N9: 118 - XII | P9: 118 - XVIII
B10: 9B | D10: 36 | F10: 72 | H10: 103 | I10: 2 | J10: 11 | L10: 48 | N10: 73 | O10: 1-9 | P10: 87 | Q10: 2-10a
B11: 10 | D11: 36 | F11: 72 | H11: 103 | I11: 3 | J11: 12 | L11: 48 | N11: 73 | O11: 10-23 | P11: 87 | Q11: 10b-19
A12: Mercredi | B12: 15 | C12: 17 | D12: 37 | F12: 77 | H12: 104 | J12: 118 - II | L12: 118 - I | N12: 118 - XIII | P12: 118 - XIX
B13: 23 | C13: 17 | D13: 37 | F13: 77 | H13: 104 | J13: 13 | L13: 52 | N13: 11 | P13: 93 | Q13: 1-11
B14: 65 | C14: 17 | D14: 38 | F14: 77 | H14: 104 | J14: 14 | L14: 53 | N14: 74 | P14: 93 | Q14: 12-23
A15: Jeudi | B15: 67 | C15: 17 | D15: 43 | F15: 77 | H15: 105 | J15: 118 - III | L15: 118 - VIII | N15: 118 - XIV | P15: 118 - XX
B16: 67 | C16: 17 | D16: 43 | F16: 77 | H16: 105 | J16: 41 | L16: 54 | N16: 80 | P16: 127
B17: 67 | C17: 17 | D17: 43 | F17: 77 | H17: 105 | J17: 42 | L17: 54 | N17: 80 | P17: 128
A18: Vendredi | B18: 19 | E18: 49 | F18: 78 | H18: 106 | J18: 118 - IV | L18: 118 - IX | N18: 21 | O18: 2-11 | P18: 118 - XXI
B19: 20 | D19: 51 | E19: 51 | F19: 82 | H19: 106 | J19: 25 | L19: 55 | N19: 21 | O19: 12-22 | P19: 132
B20: 29 | D20: 57 | E20: 57 | F20: 100 | H20: 106 | J20: 27 | L20: 60 | N20: 21 | O20: 23-32 | P20: 137
A21: Samedi | B21: 30 | D21: 58 | F21: 101 | H21: 108 | J21: 118 - V | L21: 118 - X | N21: 118 - XV | P21: 118 - XXII
B22: 30 | D22: 58 | F22: 101 | H22: 108 | J22: 33 | K22: 2-11 | L22: 61 | N22: 33 | O22: 2-11 | P22: 44 | Q22: 2-10
B23: 30 | D23: 59 | F23: 101 | H23: 108 | J23: 33 | K23: 12-23 | L23: 63 | N23: 33 | O23: 12-23 | P23: 44 | Q23: 11-18
J24: REPARTITION FR. JEAN-BAPTISTE
A27: Dimanche | B27: 1 | C27: 65 | D27: 12 | E27: 67 | F27: 17 | G27: 88 | H27: 29 | I27: 103 | J27: 117 | K27: 1-4 | L27: 22 | N27: 117 | O27: 1-4 | P27: 22
B28: 2 | C28: 75 | D28: 15 | E28: 67 | F28: 17 | G28: 88 | H28: 49 | I28: 103 | J28: 117 | K28: 5-24 | L28: 75 | M28: 2-7 | N28: 117 | O28: 5-24 | P28: 75 | Q28: 2-7
B29: 3 | C29: 75 | D29: 23 | E29: 67 | F29: 17 | G29: 88 | H29: 49 | I29: 103 | J29: 117 | K29: 25-29 | L29: 75 | M29: 8-13 | N29: 117 | O29: 25-29 | P29: 75 | Q29: 8-13
A30: Lundi | J30: 18B | L30: 118 - VI | N30: 118 - XI | P30: 118 - XVII
J31: 7 | K31: 2-10 | L31: 39 | M31: 2-9 | N31: 70 | O31: 1-13 | P31: 81
J32: 7 | K32: 11-18 | L32: 39 | M32: 10-18 | N32: 70 | O32: 14-24 | P32: 119
A33: Mardi | J33: 118 - I | L33: 118 - VII | N33: 118 - XII | P33: 118 - XVIII
J34: 12 | L34: 52 | N34: 73 | O34: 1-9 | P34: 87 | Q34: 2-10a
J35: 13 | L35: 53 | N35: 73 | O35: 10-23 | P35: 87 | Q35: 10b-19
A36: Mercredi | J36: 118 - II | L36: 118 - I | N36: 118 - XIII | P36: 118 - XIX
J37: 10 | L37: 54 | M37: 2-16 | N37: 11 | P37: 93 | Q37: 1-11
J38: 14 | L38: 54 | M38: 17-24 | N38: 74 | P38: 93 | Q38: 12-23
A39: Jeudi | J39: 118 - III | L39: 118 - VIII | N39: 118 - XIV | P39: 118 - XX
J40: 41 | L40: 55 | N40: 80 | P40: 127
J41: 42 | L41: 61 | N41: 80 | P41: 128
A42: Vendredi | J42: 118 - IV | L42: 118 - IX | N42: 21 | O42: 2-11 | P42: 118 - XXI
...

Sheet Carême G
B1: Office des Lectures | G1: Laudes | I1: Milieu du Jour | M1: Vêpres
B2: I | C2: II | D2: III | E2: IV | F2: V | G2: I | H2: II | I2: I | J2: II | K2: III | L2: IV | M2: I | N2: II
A3: Samedi | M3: 139 | N3: 141
M4: 140 | N4: 142
M5: NT IV | N5: NT IV
A6: Dimanche | B6: 15 | C6: 26 | D6: 35 | E6: 17 | F6: 85 | G6: 62 | H6: 62 | I6: 117 | J6: 92 | K6: 117 | L6: 92 | M6: 109 | N6: 109
B7: 16 | C7: 66 | D7: 41 | F7: 87 | G7: AT 5 | H7: AT 5 | J7: 75 | L7: 75 | M7: 114 | N7: 114
B8: 90 | C8: 83 | D8: 45 | F8: 29 | G8: 149 | H8: 149 | M8: NT X | N8: NT X
A9: Lundi | B9: 9 | C9: 49 | D9: 88 | E9: 106 | F9: 9 | G9: 6 | H9: 55 | I9: 18 B | J9: 118-VI | K9: 118-XII | L9: 118-XVII | M9: 39, 1-9 | N9: 70, 1-13
G10: AT 4 | H10: AT 18 | I10: 5 | J10: 33 | K10: 89 | L10: 127 | M10: 39, 10-18 | N10: 70, 14-24
G11: 12 | H11: 60 | I11: 10 | L11: 128 | M11: NT V | N11: NT V
A12: Mardi | B12: 11 | C12: 67 | D12: 103 | E12: 130 | F12: 11 | G12: 25 | H12: 57 | I12: 118-I | J12: 118-VII | K12: 118-XIII | L12: 118-XVIII | M12: 43, 2-17 | N12: 72, 1-12
B13: 75 | F13: 75 | G13: AT 42 | H13: AT 42 | I13: 7 | J13: 56 | K13: 107 | L13: 130 | M13: 43, 18-27 | N13: 72, 13-28
G14: 31 | H14: 81 | L14: 132 | M14: NT IV | N14: NT IV
A15: Mercredi | B15: 30 | C15: 68 | D15: 30 | E15: 68 | F15: 30 | G15: 27 | H15: 61 | I15: 188-II | J15: 118-VIII | K15: 118-XIV | L15: 118-XIX | M15: 48, 2-13 | N15: 73, 1-11
G16: AT 45 | H16: AT 45 | I16: 13 | J16: 28 | K16: 110 | L16: 131 | M16: 48, 14-21 | N16: 73, 12-23
G17: 96 | H17: 63 | I17: 14 | J17: 59 | K17: 111 | M17: NT X | N17: NT X
A18: Jeudi | B18: 34 | C18: 77 A | D18: 104 | E18: 135 | F18: 34 | G18: 40 | H18: 69 | I18: 118-III | J18: 118-IX | K18: 118-XV | L18: 118-XX | M18: 54, 2-15 | N18: 87, 2-10
G19: AT 54 | H19: AT 54 | I19: 19 | J19: 71 | K19: 112 | L19: 134 | M19: 54, 16-24 | N19: 87, 11-19
G20: 53 | H20: 82 | I20: 20 | K20: 113 B | M20: NT V | N20: NT V
A21: Vendredi | B21: 37 | C21: 21 | D21: 37 | E21: 21 | F21: 37 | G21: 50 | H21: 50 | I21: 118-IV | J21: 118-X | K21: 119 | L21: 118-XXI | M21: 58, 2-11 | N21: 93, 1-11
B22: 38 | D22: 38 | F22: 38 | G22: AT 56 | H22: AT 56 | I22: 24 | J22: 79 | K22: 122 | L22: 143 | M22: 58, 12-18 | N22: 93, 12-21
G23: 56 | H23: 100 | K23: 123 | M23: NT X | N23: NT X
A24: Samedi | B24: 36 | C24: 77 B | D24: 105 | E24: 144 | F24: 108 | G24: 51 | H24: 74 | I24: 118-V | J24: 118-XI | K24: 118-XVI | L24: 118-XXII
G25: AT 57 | H25: AT 57 | I25: 32 | J25: 80 | K25: 124 | L25: 144
G26: 52 | H26: 78 | J26: 84 | K26: 126
A28: Mercredi des Cendres | C28: Vigiles | D28: Laudes | E28: Millieu du Jour | F28: Vêpres
C29: 101, 2-12 | D29: 50 | E29: 118-XIX | F29: 129
C30: 101, 13-23 | D30: AT 42 | E30: 93 | F30: 136
C31: 101, 24-28 | D31: 31 | F31: NT X

Sheet Oct. pasc R+G
A1: Répartion Gouzantine/Toulouse | K1: Répartition Romaine
B2: Vigiles | D2: Laudes | E2: Milieu du Jour | G2: Vêpres | I2: Complies | L2: Vigiles | N2: Laudes | O2: Milieu du Jour | Q2: Vêpres | S2: Complies
A3: Dimanche | D3: 117 | G3: 109 | I3: 90 | K3: Dimanche | N3: 62 | O3: 117 | Q3: 109 | S3: 90
D4: AT 1 | G4: 113A | N4: AT 49 | O4: 117 | Q4: 113 A
D5: 150 | G5: NT XIV | N5: 149 | O5: 117 | Q5: NT XIV
A6: Lundi | B6: 11 | D6: 92 | G6: 109 | I6: 90 | K6: Lundi | L6: 1 | N6: 62 | O6: 8 | Q6: 109 | S6: 90
B7: 15 | D7: AT 1 | G7: 113A | L7: 2 | N7: AT 49 | O7: 18A | Q7: 113 A
B8: 22 | D8: 150 | G8: NT XIV | L8: 3 | N8: 149 | O8: 18B | Q8: NT XIV
A9: Mardi | B9: 23 | D9: 92 | G9: 109 | I9: 90 | K9: Mardi | L9: 23 | N9: 62 | O9: 118 I | Q9: 109 | S9: 90
B10: 65 | D10: AT 1 | G10: 113A | L10: 65, 1-12 | N10: AT 49 | O10: 15 | Q10: 113 A
B11: 65 | D11: 150 | G11: NT XIV | L11: 65, 13-20 | N11: 149 | O11: 22 | Q11: NT XIV
A12: Mercredi | B12: 29 | D12: 92 | G12: 109 | I12: 90 | K12: Mercredi | L12: 103, 1-12 | N12: 62 | O12: 118-II | Q12: 109 | S12: 90
B13: 76 | D13: AT 1 | G13: 113A | L13: 103, 13-23 | N13: AT 49 | O13: 27 | Q13: 113 A
B14: 76 | D14: 150 | G14: NT XIV | L14: 103, 24-35 | N14: 149 | O14: 115 | Q14: NT XIV
A15: Jeudi | B15: 104 | D15: 92 | G15: 109 | I15: 90 | K15: Jeudi | L15: 117, 1-4 | N15: 62 | O15: 118-III | Q15: 109 | S15: 90
B16: 104 | D16: AT 1 | G16: 113A | L16: 117, 5-24 | N16: AT 49 | O16: 29, 1-6 | Q16: 113 A
B17: 104 | D17: 150 | G17: NT XIV | L17: 117, 25-29 | N17: 149 | O17: 29, 7-13 | Q17: NT XIV
A18: Vendredi | B18: 105 | D18: 92 | G18: 109 | I18: 90 | K18: Vendredi | L18: 135, 1-9 | N18: 62 | O18: 118-IV | Q18: 109 | S18: 90
B19: 105 | D19: AT 1 | G19: 113A | L19: 135, 10-15 | N19: AT 49 | O19: 75, 1-7 | Q19: 113 A
B20: 105 | D20: 150 | G20: NT XIV | L20: 135, 16-26 | N20: 149 | O20: 75, 8-13 | Q20: NT XIV
A21: Samedi | B21: 75 | D21: 92 | G21: 135 | I21: 90 | K21: Samedi | L21: 144 | N21: 62 | O21: 118-V | Q21: 109 | S21: 90
B22: 144 | D22: AT 1 | G22: 135 | L22: 144 | N22: AT 49 | O22: 95 | P22: 1-6 | Q22: 113 A
B23: 144 | D23: 150 | G23: NT XIV | L23: 144 | N23: 149 | O23: 95 | P23: 7-13 | Q23: NT XIV
A24: Dimanche | B24: 1 | D24: 117 | G24: 109 | I24: 90 | K24: Dimanche | L24: 1 | N24: 62 | O24: 117 | Q24: 109 | S24: 90
B25: 2 | D25: AT 1 | G25: 113A | L25: 2 | N25: AT 49 | O25: 117 | Q25: 113 A
B26: 3 | D26: 150 | G26: NT XIV | L26: 3 | N26: 149 | O26: 117 | Q26: NT XIV

Sheet TPG Travail
B1: Laudes
B2: I | C2: II
A3: Dimanche | B3: 117 | C3: 117 | E3: 1 | F3: =VLOOKUP($E3,$B$1:$B$161,1,FALSE) -> 1 | G3: =VLOOKUP($E3,$C$1:$C$161,1,FALSE) -> 1 | H3: =IF(ISNA(F3),IF(ISNA(G3),FALSE,E3),E3) -> 1
B4: AT 1 | C4: AT 1 | E4: 2 | F4: =VLOOKUP($E4,$B$1:$B$161,1,FALSE) -> 2 | G4: =VLOOKUP($E4,$C$1:$C$161,1,FALSE) -> 2 | H4: =IF(ISNA(F4),IF(ISNA(G4),FALSE,E4),E4) -> 2
B5: 150 | C5: 150 | E5: 3 | F5: =VLOOKUP($E5,$B$1:$B$161,1,FALSE) -> 3 | G5: =VLOOKUP($E5,$C$1:$C$161,1,FALSE) -> 3 | H5: =IF(ISNA(F5),IF(ISNA(G5),FALSE,E5),E5) -> 3
A6: Lundi | B6: 8 | C6: 46 | E6: 4 | F6: =VLOOKUP($E6,$B$1:$B$161,1,FALSE) -> 4 | G6: =VLOOKUP($E6,$C$1:$C$161,1,FALSE) -> #N/A | H6: =IF(ISNA(F6),IF(ISNA(G6),FALSE,E6),E6) -> 4
B7: AT 50 | C7: AT 50 | E7: 5 | F7: =VLOOKUP($E7,$B$1:$B$161,1,FALSE) -> #N/A | G7: =VLOOKUP($E7,$C$1:$C$161,1,FALSE) -> #N/A | H7: =IF(ISNA(F7),IF(ISNA(G7),FALSE,E7),E7) -> FALSE
B8: 91 | C8: 112-116 | E8: 6 | F8: =VLOOKUP($E8,$B$1:$B$161,1,FALSE) -> 6 | G8: =VLOOKUP($E8,$C$1:$C$161,1,FALSE) -> #N/A | H8: =IF(ISNA(F8),IF(ISNA(G8),FALSE,E8),E8) -> 6
A9: Mardi | B9: 18A | C9: 47 | E9: 7 | F9: =VLOOKUP($E9,$B$1:$B$161,1,FALSE) -> 7 | G9: =VLOOKUP($E9,$C$1:$C$161,1,FALSE) -> #N/A | H9: =IF(ISNA(F9),IF(ISNA(G9),FALSE,E9),E9) -> 7
B10: AT 55 | C10: AT 55 | E10: 8 | F10: =VLOOKUP($E10,$B$1:$B$161,1,FALSE) -> 8 | G10: =VLOOKUP($E10,$C$1:$C$161,1,FALSE) -> #N/A | H10: =IF(ISNA(F10),IF(ISNA(G10),FALSE,E10),E10) -> 8
B11: 95 | C11: 134 | E11: 9 | F11: =VLOOKUP($E11,$B$1:$B$161,1,FALSE) -> #N/A | G11: =VLOOKUP($E11,$C$1:$C$161,1,FALSE) -> #N/A | H11: =IF(ISNA(F11),IF(ISNA(G11),FALSE,E11),E11) -> FALSE
A12: Mercredi | B12: 23 | C12: 62 | E12: 10 | F12: =VLOOKUP($E12,$B$1:$B$161,1,FALSE) -> 10 | G12: =VLOOKUP($E12,$C$1:$C$161,1,FALSE) -> #N/A | H12: =IF(ISNA(F12),IF(ISNA(G12),FALSE,E12),E12) -> 10
B13: AT 51 | C13: AT 51 | E13: 11 | F13: =VLOOKUP($E13,$B$1:$B$161,1,FALSE) -> 11 | G13: =VLOOKUP($E13,$C$1:$C$161,1,FALSE) -> #N/A | H13: =IF(ISNA(F13),IF(ISNA(G13),FALSE,E13),E13) -> 11
B14: 96 | C14: 145 | E14: 12 | F14: =VLOOKUP($E14,$B$1:$B$161,1,FALSE) -> 12 | G14: =VLOOKUP($E14,$C$1:$C$161,1,FALSE) -> #N/A | H14: =IF(ISNA(F14),IF(ISNA(G14),FALSE,E14),E14) -> 12
A15: Jeudi | B15: 27 | C15: 64 | E15: 13 | F15: =VLOOKUP($E15,$B$1:$B$161,1,FALSE) -> 13 | G15: =VLOOKUP($E15,$C$1:$C$161,1,FALSE) -> #N/A | H15: =IF(ISNA(F15),IF(ISNA(G15),FALSE,E15),E15) -> 13
B16: AT 36 | C16: AT 36 | E16: 14 | F16: =VLOOKUP($E16,$B$1:$B$161,1,FALSE) -> 14 | G16: =VLOOKUP($E16,$C$1:$C$161,1,FALSE) -> #N/A | H16: =IF(ISNA(F16),IF(ISNA(G16),FALSE,E16),E16) -> 14
B17: 97 | C17: 146 | E17: 15 | F17: =VLOOKUP($E17,$B$1:$B$161,1,FALSE) -> 15 | G17: =VLOOKUP($E17,$C$1:$C$161,1,FALSE) -> #N/A | H17: =IF(ISNA(F17),IF(ISNA(G17),FALSE,E17),E17) -> 15
A18: Vendredi | B18: 35 | C18: 83 | E18: 16 | F18: =VLOOKUP($E18,$B$1:$B$161,1,FALSE) -> #N/A | G18: =VLOOKUP($E18,$C$1:$C$161,1,FALSE) -> #N/A | H18: =IF(ISNA(F18),IF(ISNA(G18),FALSE,E18),E18) -> FALSE
B19: AT 52 | C19: AT 52 | E19: 17 | F19: =VLOOKUP($E19,$B$1:$B$161,1,FALSE) -> #N/A | G19: =VLOOKUP($E19,$C$1:$C$161,1,FALSE) -> #N/A | H19: =IF(ISNA(F19),IF(ISNA(G19),FALSE,E19),E19) -> FALSE
B20: 98 | C20: 147 | E20: 18 | F20: =VLOOKUP($E20,$B$1:$B$161,1,FALSE) -> #N/A | G20: =VLOOKUP($E20,$C$1:$C$161,1,FALSE) -> #N/A | H20: =IF(ISNA(F20),IF(ISNA(G20),FALSE,E20),E20) -> FALSE
A21: Samedi | B21: 45 | C21: 86 | E21: 19 | F21: =VLOOKUP($E21,$B$1:$B$161,1,FALSE) -> 19 | G21: =VLOOKUP($E21,$C$1:$C$161,1,FALSE) -> #N/A | H21: =IF(ISNA(F21),IF(ISNA(G21),FALSE,E21),E21) -> 19
B22: AT 59 | C22: AT 59 | E22: 20 | F22: =VLOOKUP($E22,$B$1:$B$161,1,FALSE) -> 20 | G22: =VLOOKUP($E22,$C$1:$C$161,1,FALSE) -> #N/A | H22: =IF(ISNA(F22),IF(ISNA(G22),FALSE,E22),E22) -> 20
B23: 99 | C23: 149 | E23: 21 | F23: =VLOOKUP($E23,$B$1:$B$161,1,FALSE) -> 21 | G23: =VLOOKUP($E23,$C$1:$C$161,1,FALSE) -> #N/A | H23: =IF(ISNA(F23),IF(ISNA(G23),FALSE,E23),E23) -> 21
B24: Vêpres | C24: Vêpres | E24: 22 | F24: =VLOOKUP($E24,$B$1:$B$161,1,FALSE) -> 22 | G24: =VLOOKUP($E24,$C$1:$C$161,1,FALSE) -> 22 | H24: =IF(ISNA(F24),IF(ISNA(G24),FALSE,E24),E24) -> 22
B25: I | C25: II | E25: 23 | F25: =VLOOKUP($E25,$B$1:$B$161,1,FALSE) -> 23 | G25: =VLOOKUP($E25,$C$1:$C$161,1,FALSE) -> #N/A | H25: =IF(ISNA(F25),IF(ISNA(G25),FALSE,E25),E25) -> 23
B26: 109 | C26: 109 | E26: 24 | F26: =VLOOKUP($E26,$B$1:$B$161,1,FALSE) -> #N/A | G26: =VLOOKUP($E26,$C$1:$C$161,1,FALSE) -> #N/A | H26: =IF(ISNA(F26),IF(ISNA(G26),FALSE,E26),E26) -> FALSE
B27: 113A | C27: 113A | E27: 25 | F27: =VLOOKUP($E27,$B$1:$B$161,1,FALSE) -> 25 | G27: =VLOOKUP($E27,$C$1:$C$161,1,FALSE) -> #N/A | H27: =IF(ISNA(F27),IF(ISNA(G27),FALSE,E27),E27) -> 25
B28: NT XIV | C28: NT XIV | E28: 26 | F28: =VLOOKUP($E28,$B$1:$B$161,1,FALSE) -> #N/A | G28: =VLOOKUP($E28,$C$1:$C$161,1,FALSE) -> #N/A | H28: =IF(ISNA(F28),IF(ISNA(G28),FALSE,E28),E28) -> FALSE
B29: 15 | C29: 102 | E29: 27 | F29: =VLOOKUP($E29,$B$1:$B$161,1,FALSE) -> 27 | G29: =VLOOKUP($E29,$C$1:$C$161,1,FALSE) -> #N/A | H29: =IF(ISNA(F29),IF(ISNA(G29),FALSE,E29),E29) -> 27
B30: 22 | C30: 102 | E30: 28 | F30: =VLOOKUP($E30,$B$1:$B$161,1,FALSE) -> #N/A | G30: =VLOOKUP($E30,$C$1:$C$161,1,FALSE) -> #N/A | H30: =IF(ISNA(F30),IF(ISNA(G30),FALSE,E30),E30) -> FALSE
B31: NT VI | C31: NT VI | E31: 29 | F31: =VLOOKUP($E31,$B$1:$B$161,1,FALSE) -> 29 | G31: =VLOOKUP($E31,$C$1:$C$161,1,FALSE) -> #N/A | H31: =IF(ISNA(F31),IF(ISNA(G31),FALSE,E31),E31) -> 29
B32: 29 | C32: 114 | E32: 30 | F32: =VLOOKUP($E32,$B$1:$B$161,1,FALSE) -> 30 | G32: =VLOOKUP($E32,$C$1:$C$161,1,FALSE) -> #N/A | H32: =IF(ISNA(F32),IF(ISNA(G32),FALSE,E32),E32) -> 30
B33: 42 | C33: 115 | E33: 31 | F33: =VLOOKUP($E33,$B$1:$B$161,1,FALSE) -> #N/A | G33: =VLOOKUP($E33,$C$1:$C$161,1,FALSE) -> #N/A | H33: =IF(ISNA(F33),IF(ISNA(G33),FALSE,E33),E33) -> FALSE
B34: NT XI | C34: NT XI | E34: 32 | F34: =VLOOKUP($E34,$B$1:$B$161,1,FALSE) -> #N/A | G34: =VLOOKUP($E34,$C$1:$C$161,1,FALSE) -> #N/A | H34: =IF(ISNA(F34),IF(ISNA(G34),FALSE,E34),E34) -> FALSE
B35: 44 | C35: 120 | E35: 33 | F35: =VLOOKUP($E35,$B$1:$B$161,1,FALSE) -> 33 | G35: =VLOOKUP($E35,$C$1:$C$161,1,FALSE) -> #N/A | H35: =IF(ISNA(F35),IF(ISNA(G35),FALSE,E35),E35) -> 33
B36: 44 | C36: 121 | E36: 34 | F36: =VLOOKUP($E36,$B$1:$B$161,1,FALSE) -> #N/A | G36: =VLOOKUP($E36,$C$1:$C$161,1,FALSE) -> 34 | H36: =IF(ISNA(F36),IF(ISNA(G36),FALSE,E36),E36) -> 34
B37: NT VIII | C37: NT VIII | E37: 35 | F37: =VLOOKUP($E37,$B$1:$B$161,1,FALSE) -> 35 | G37: =VLOOKUP($E37,$C$1:$C$161,1,FALSE) -> #N/A | H37: =IF(ISNA(F37),IF(ISNA(G37),FALSE,E37),E37) -> 35
B38: 65 | C38: 125 | E38: 36 | F38: =VLOOKUP($E38,$B$1:$B$161,1,FALSE) -> #N/A | G38: =VLOOKUP($E38,$C$1:$C$161,1,FALSE) -> 36 | H38: =IF(ISNA(F38),IF(ISNA(G38),FALSE,E38),E38) -> 36
B39: 65 | C39: 137 | E39: 37 | F39: =VLOOKUP($E39,$B$1:$B$161,1,FALSE) -> #N/A | G39: =VLOOKUP($E39,$C$1:$C$161,1,FALSE) -> 37 | H39: =IF(ISNA(F39),IF(ISNA(G39),FALSE,E39),E39) -> 37
B40: NT XII | C40: NT XII | E40: 38 | F40: =VLOOKUP($E40,$B$1:$B$161,1,FALSE) -> #N/A | G40: =VLOOKUP($E40,$C$1:$C$161,1,FALSE) -> 38 | H40: =IF(ISNA(F40),IF(ISNA(G40),FALSE,E40),E40) -> 38
...

Sheet TP G
B1: Laudes | D1: Vêpres | E1: Vêpres | F1: Vigiles | G1: Vigiles | H1: Vigiles | I1: Vigiles | J1: Milieu du Jour | K1: Milieu du Jour | L1: Milieu du Jour | M1: Milieu du Jour | N1: Complies | P1: 1 | Q1: 1 | R1: 1 | S1: 1
B2: I | C2: II | D2: I | E2: II | F2: I | G2: II | H2: III | I2: IV | J2: I | K2: II | L2: III | M2: IV | P2: 2 | Q2: 2 | R2: 2 | S2: 2
A3: Dimanche | B3: 117 | C3: 117 | D3: 109 | E3: 109 | F3: 1 | G3: 1 | H3: 1 | I3: 1 | J3: 22 | K3: 22 | L3: 22 | M3: 22 | N3: 90 | P3: 3 | Q3: 3 | R3: 3 | S3: 3
B4: AT 1 | C4: AT 1 | D4: 113A | E4: 113A | F4: 2 | G4: 2 | H4: 2 | I4: 2 | J4: 75 | K4: 75 | L4: 75 | M4: 75 | P4: 4 | Q4: 4 | R4: #N/A | S4: 4
B5: 150 | C5: 150 | D5: NT XIV | E5: NT XIV | F5: 3 | G5: 3 | H5: 3 | I5: 3 | J5: 75 | K5: 75 | L5: 75 | M5: 75 | O5: x | P5: 5 | Q5: #N/A | R5: #N/A | S5: FALSE
A6: Lundi | B6: 8 | C6: 46 | D6: 15 | E6: 102 | F6: 5 | G6: 34 | H6: 68 | J6: 18B | K6: 118 - VI | L6: 118 - XI | M6: 118 - XVII | N6: 4 | P6: 6 | Q6: 6 | R6: #N/A | S6: 6
B7: AT 50 | C7: AT 50 | D7: 22 | E7: 102 | F7: 6 | G7: 34 | H7: 68 | J7: 7 | K7: 39 | L7: 70 | M7: 81 | N7: 133 | P7: 7 | Q7: 7 | R7: #N/A | S7: 7
B8: 91 | C8: 112-116 | D8: NT VI | E8: NT VI | G8: 34 | H8: 68 | J8: 7 | K8: 39 | L8: 70 | M8: 119 | P8: 8 | Q8: 8 | R8: #N/A | S8: 8
A9: Mardi | B9: 18A | C9: 47 | D9: 29 | E9: 114 | F9: 9A | G9: 36 | H9: 72 | I9: 103 | J9: 118 - I | K9: 118 - VII | L9: 118 - XII | M9: 118 - XVIII | N9: 90 | P9: 9 | Q9: #N/A | R9: #N/A | S9: 9
B10: AT 55 | C10: AT 55 | D10: 42 | E10: 115 | F10: 9B | G10: 36 | H10: 72 | I10: 103 | J10: 11 | K10: 48 | L10: 73 | M10: 87 | P10: 10 | Q10: 10 | R10: #N/A | S10: 10
B11: 95 | C11: 134 | D11: NT XI | E11: NT XI | F11: 10 | G11: 36 | H11: 72 | I11: 103 | J11: 12 | K11: 48 | L11: 73 | M11: 87 | P11: 11 | Q11: 11 | R11: #N/A | S11: 11
A12: Mercredi | B12: 23 | C12: 62 | D12: 44 | E12: 120 | G12: 37 | H12: 77 | I12: 104 | J12: 118 - II | K12: 118 - I | L12: 118 - XIII | M12: 118 - XIX | N12: 4 | P12: 12 | Q12: 12 | R12: #N/A | S12: 12
B13: AT 51 | C13: AT 51 | D13: 44 | E13: 121 | G13: 37 | H13: 77 | I13: 104 | J13: 13 | K13: 52 | L13: 74 | M13: 93 | N13: 133 | P13: 13 | Q13: 13 | R13: #N/A | S13: 13
B14: 96 | C14: 145 | D14: NT VIII | E14: NT VIII | G14: 38 | H14: 77 | I14: 104 | J14: 14 | K14: 53 | M14: 93 | P14: 14 | Q14: 14 | R14: #N/A | S14: 14
A15: Jeudi | B15: 27 | C15: 64 | D15: 65 | E15: 125 | F15: 67 | G15: 43 | H15: 77 | I15: 105 | J15: 118 - III | K15: 118 - VIII | L15: 118 - XIV | M15: 118 - XX | N15: 90 | P15: 15 | Q15: 15 | R15: #N/A | S15: 15
B16: AT 36 | C16: AT 36 | D16: 65 | E16: 137 | F16: 67 | G16: 43 | H16: 77 | I16: 105 | J16: 41 | K16: 54 | L16: 80 | M16: 127 | P16: 16 | Q16: #N/A | R16: #N/A | S16: FALSE
B17: 97 | C17: 146 | D17: NT XII | E17: NT XII | F17: 67 | G17: 43 | H17: 77 | I17: 105 | K17: 54 | L17: 80 | M17: 128 | P17: 17 | Q17: #N/A | R17: #N/A | S17: FALSE
A18: Vendredi | B18: 35 | C18: 83 | D18: 76 | E18: 138 | F18: 19 | H18: 78 | I18: 106 | J18: 118 - IV | K18: 118 - IX | L18: 21 | M18: 118 - XXI | N18: 4 | P18: 18 | Q18: #N/A | R18: #N/A | S18: FALSE
B19: AT 52 | C19: AT 52 | D19: 76 | E19: 138 | F19: 20 | G19: 51 | H19: 82 | I19: 106 | J19: 25 | K19: 55 | L19: 21 | M19: 132 | N19: 133 | P19: 19 | Q19: 19 | R19: #N/A | S19: 19
B20: 98 | C20: 147 | D20: NT XIII | E20: NT XIII | G20: 57 | H20: 100 | I20: 106 | K20: 60 | L20: 21 | P20: 20 | Q20: 20 | R20: #N/A | S20: 20
A21: Samedi | B21: 45 | C21: 86 | D21: 135 | E21: 135 | F21: 30 | G21: 58 | H21: 101 | I21: 108 | J21: 118 - V | K21: 118 - X | L21: 118 - XV | M21: 118 - XXII | N21: 4 | P21: 21 | Q21: 21 | R21: #N/A | S21: 21
B22: AT 59 | C22: AT 59 | D22: 135 | E22: 135 | F22: 30 | G22: 58 | H22: 101 | I22: 108 | J22: 33 | K22: 61 | L22: 33 | N22: 133 | P22: 22 | Q22: 22 | R22: 22 | S22: 22
B23: 99 | C23: 149 | D23: NT VII | E23: NT VII | F23: 30 | G23: 59 | H23: 101 | I23: 108 | J23: 33 | K23: 63 | L23: 33 | P23: 23 | Q23: 23 | R23: #N/A | S23: 23
P24: 24 | Q24: #N/A | R24: #N/A | S24: FALSE
P25: 25 | Q25: 25 | R25: #N/A | S25: 25
A26: 1 | D26: 51 | G26: 101 | P26: 26 | Q26: #N/A | R26: #N/A | S26: FALSE
A27: 2 | D27: 52 | G27: 102 | P27: 27 | Q27: 27 | R27: #N/A | S27: 27
A28: 3 | D28: 53 | G28: 103 | P28: 28 | Q28: #N/A | R28: #N/A | S28: FALSE
A29: 4 | D29: 54 | G29: 104 | P29: 29 | Q29: 29 | R29: #N/A | S29: 29
A30: 5 | D30: 55 | G30: 105 | P30: 30 | Q30: 30 | R30: #N/A | S30: 30
A31: 6 | D31: 56 | G31: 106 | P31: 31 | Q31: #N/A | R31: #N/A | S31: FALSE
A32: 7 | D32: 57 | G32: 107 | P32: 32 | Q32: #N/A | R32: #N/A | S32: FALSE
A33: 8 | D33: 58 | G33: 108 | P33: 33 | Q33: 33 | R33: #N/A | S33: 33
A34: 9 | D34: 59 | G34: 109 | P34: 34 | Q34: #N/A | R34: 34 | S34: 34
A35: 10 | D35: 60 | G35: 110 | P35: 35 | Q35: 35 | R35: #N/A | S35: 35
A36: 11 | D36: 61 | G36: 111 | P36: 36 | Q36: #N/A | R36: 36 | S36: 36
A37: 12 | D37: 62 | G37: 112 | P37: 37 | Q37: #N/A | R37: 37 | S37: 37
A38: 13 | D38: 63 | G38: 113 | P38: 38 | Q38: #N/A | R38: 38 | S38: 38
A39: 14 | D39: 64 | G39: 114 | P39: 39 | Q39: #N/A | R39: 39 | S39: 39
A40: 15 | D40: 65 | G40: 115 | P40: 40 | Q40: #N/A | R40: #N/A | S40: FALSE
...

Sheet Asc.-Pentecôte
B1: Vigiles | D1: Laudes | E1: Milieu du jour | G1: Vêpres | I1: Complies
A2: Mercredi | G2: 112-116 | I2: 4
G3: 148 | I3: 133
G4: NT XIV
A5: Jeudi | B5: 67 | D5: 92 | G5: 109 | I5: 90
B6: 67 | D6: AT 58 | G6: 46
B7: 67 | D7: 150 | G7: NT XII
A8: Vendredi | B8: 8 | D8: 32 | G8: 15 | I8: 4
B9: 18A | D9: AT 53 | G9: 22 | I9: 133
B10: 23 | D10: 99 | G10: NT XIII
A11: Samedi | B11: 26 | D11: 56 | G11: 135 | I11: 4
B12: 26 | D12: AT 31 | G12: 135 | I12: 133
B13: 28 | D13: 145 | G13: NT VII
A14: Dimanche | B14: 41 | D14: 92 | G14: 109 | I14: 90
B15: 102 | D15: AT 58 | G15: 46
B16: 102 | D16: 150 | G16: NT XIV
A17: Lundi | B17: 35 | D17: 84 | G17: 114 | I17: 4
B18: 45 | D18: AT 41 | G18: 115 | I18: 133
B19: 47 | D19: 146 | G19: NT VI
A20: Mardi | B20: 64 | D20: 86 | G20: 121 | I20: 90
B21: 144 | D21: AT 46 | G21: 125
B22: 144 | D22: 147 | G22: NT XI
A23: Mercredi | B23: 8 | D23: 32 | G23: 15 | I23: 4
B24: 18A | D24: AT 53 | G24: 22 | I24: 133
B25: 23 | D25: 99 | G25: NT VIII
A26: Jeudi | B26: 26 | D26: 56 | G26: 44 | I26: 90
B27: 26 | D27: AT 31 | G27: 44
B28: 28 | D28: 145 | G28: NT XII
A29: Vendredi | B29: 35 | D29: 84 | G29: 114 | I29: 4
B30: 45 | D30: AT 41 | G30: 115 | I30: 133
B31: 47 | D31: 146 | G31: NT XIII
A32: Samedi | B32: 64 | D32: 86 | G32: 116 | I32: 4
B33: 144 | D33: AT 46 | G33: 146 | I33: 133
B34: 144 | D34: 147 | G34: NT XIII
A35: Dimanche | B35: 103 | D35: 92 | G35: 135 | I35: 90
B36: 103 | D36: AT 49 | G36: 135
B37: 103 | D37: 148 | G37: NT XIII

Sheet 1962
B1: Matines 1 | E1: Matines 2 | H1: Matines 3 | K1: Laudes | P1: Prime | S1: Tierce | V1: Sexte | Y1: None | AB1: Vêpres | AG1: Complies
A2: Dimanche | B2: 1 | C2: 2 | D2: 3 | E2: 8 | F2: 9 | G2: 9 | H2: 9 | I2: 9 | J2: 10 | K2: 92 | L2: 99 | M2: 62 | O2: 148 | P2: 117 | Q2: 118 | R2: 118 | S2: 118 | T2: 118 | U2: 118 | V2: 118 | W2: 118 | X2: 118 | Y2: 118 | Z2: 118 | AA2: 118 | AB2: 109 | AC2: 110 | AD2: 111 | AE2: 112 | AF2: 113 | AG2: 4 | AH2: 90 | AI2: 133
A3: Lundi | B3: 13 | C3: 14 | D3: 16 | E3: 17 | F3: 17 | G3: 17 | H3: 19 | I3: 20 | J3: 29 | K3: 46 | L3: 5 | M3: 28 | O3: 116 | P3: 23 | Q3: 18 | R3: 18 | S3: 26 | T3: 26 | U3: 27 | V3: 30 | W3: 30 | X3: 30 | Y3: 31 | Z3: 32 | AA3: 32 | AB3: 114 | AC3: 115 | AD3: 119 | AE3: 120 | AF3: 121 | AG3: 6 | AH3: 7 | AI3: 7
A4: Mardi | B4: 34 | C4: 34 | D4: 34 | E4: 36 | F4: 36 | G4: 36 | H4: 37 | I4: 37 | J4: 38 | K4: 95 | L4: 42 | M4: 66 | O4: 134 | P4: 24 | Q4: 24 | R4: 24 | S4: 39 | T4: 39 | U4: 39 | V4: 40 | W4: 41 | X4: 41 | Y4: 43 | Z4: 43 | AA4: 43 | AB4: 122 | AC4: 123 | AD4: 124 | AE4: 125 | AF4: 126 | AG4: 11 | AH4: 12 | AI4: 15
A5: Mercredi | B5: 44 | C5: 44 | D5: 45 | E5: 47 | F5: 48 | G5: 48 | H5: 49 | I5: 49 | J5: 50 | K5: 96 | L5: 64 | M5: 100 | O5: 145 | P5: 25 | Q5: 51 | R5: 52 | S5: 53 | T5: 54 | U5: 54 | V5: 55 | W5: 56 | X5: 57 | Y5: 58 | Z5: 58 | AA5: 59 | AB5: 127 | AC5: 128 | AD5: 129 | AE5: 130 | AF5: 131 | AG5: 33 | AH5: 33 | AI5: 60
A6: Jeudi | B6: 61 | C6: 65 | D6: 65 | E6: 67 | F6: 67 | G6: 67 | H6: 68 | I6: 68 | J6: 68 | K6: 97 | L6: 89 | M6: 35 | O6: 146 | P6: 22 | Q6: 71 | R6: 71 | S6: 72 | T6: 72 | U6: 72 | V6: 73 | W6: 73 | X6: 73 | Y6: 74 | Z6: 75 | AA6: 75 | AB6: 132 | AC6: 135 | AD6: 135 | AE6: 136 | AF6: 137 | AG6: 69 | AH6: 70 | AI6: 70
A7: Vendredi | B7: 77 | C7: 77 | D7: 77 | E7: 77 | F7: 77 | G7: 77 | H7: 78 | I7: 80 | J7: 82 | K7: 98 | L7: 142 | M7: 84 | O7: 147 | P7: 21 | Q7: 21 | R7: 21 | S7: 79 | T7: 79 | U7: 81 | V7: 83 | W7: 83 | X7: 86 | Y7: 88 | Z7: 88 | AA7: 88 | AB7: 138 | AC7: 138 | AD7: 139 | AE7: 140 | AF7: 141 | AG7: 76 | AH7: 76 | AI7: 85
A8: Samedi | B8: 104 | C8: 104 | D8: 104 | E8: 105 | F8: 105 | G8: 105 | H8: 106 | I8: 106 | J8: 106 | K8: 149 | L8: 91 | M8: 63 | O8: 148 | P8: 93 | Q8: 93 | R8: 107 | S8: 101 | T8: 101 | U8: 101 | V8: 103 | W8: 103 | X8: 103 | Y8: 108 | Z8: 108 | AA8: 108 | AB8: 143 | AC8: 143 | AD8: 144 | AE8: 144 | AF8: 144 | AG8: 87 | AH8: 102 | AI8: 102

Sheet 1962 (2)
B1: Matines 1 | E1: Matines 2 | H1: Matines 3 | K1: Laudes
A2: Dimanche | B2: 1 | C2: 2 | D2: 3 | E2: 8 | F2: 9 | G2: 9 | H2: 9 | I2: 9 | J2: 10 | K2: 92 | L2: 99 | M2: 62 | O2: 148
A3: Lundi | B3: 13 | C3: 14 | D3: 16 | E3: 17 | F3: 17 | G3: 17 | H3: 19 | I3: 20 | J3: 29 | K3: 46 | L3: 5 | M3: 28 | O3: 116
A4: Mardi | B4: 34 | C4: 34 | D4: 34 | E4: 36 | F4: 36 | G4: 36 | H4: 37 | I4: 37 | J4: 38 | K4: 95 | L4: 42 | M4: 66 | O4: 134
A5: Mercredi | B5: 44 | C5: 44 | D5: 45 | E5: 47 | F5: 48 | G5: 48 | H5: 49 | I5: 49 | J5: 50 | K5: 96 | L5: 64 | M5: 100 | O5: 145
A6: Jeudi | B6: 61 | C6: 65 | D6: 65 | E6: 67 | F6: 67 | G6: 67 | H6: 68 | I6: 68 | J6: 68 | K6: 97 | L6: 89 | M6: 35 | O6: 146
A7: Vendredi | B7: 77 | C7: 77 | D7: 77 | E7: 77 | F7: 77 | G7: 77 | H7: 78 | I7: 80 | J7: 82 | K7: 98 | L7: 142 | M7: 84 | O7: 147
A8: Samedi | B8: 104 | C8: 104 | D8: 104 | E8: 105 | F8: 105 | G8: 105 | H8: 106 | I8: 106 | J8: 106 | K8: 149 | L8: 91 | M8: 63 | O8: 148
B11: Prime | E11: Tierce | H11: Sexte | K11: None | N11: Vêpres | S11: Complies
A12: Dimanche | B12: 117 | C12: 118 | D12: 118 | E12: 118 | F12: 118 | G12: 118 | H12: 118 | I12: 118 | J12: 118 | K12: 118 | L12: 118 | M12: 118 | N12: 109 | O12: 110 | P12: 111 | Q12: 112 | R12: 113 | S12: 4 | T12: 90 | U12: 133
A13: Lundi | B13: 23 | C13: 18 | D13: 18 | E13: 26 | F13: 26 | G13: 27 | H13: 30 | I13: 30 | J13: 30 | K13: 31 | L13: 32 | M13: 32 | N13: 114 | O13: 115 | P13: 119 | Q13: 120 | R13: 121 | S13: 6 | T13: 7 | U13: 7
A14: Mardi | B14: 24 | C14: 24 | D14: 24 | E14: 39 | F14: 39 | G14: 39 | H14: 40 | I14: 41 | J14: 41 | K14: 43 | L14: 43 | M14: 43 | N14: 122 | O14: 123 | P14: 124 | Q14: 125 | R14: 126 | S14: 11 | T14: 12 | U14: 15
A15: Mercredi | B15: 25 | C15: 51 | D15: 52 | E15: 53 | F15: 54 | G15: 54 | H15: 55 | I15: 56 | J15: 57 | K15: 58 | L15: 58 | M15: 59 | N15: 127 | O15: 128 | P15: 129 | Q15: 130 | R15: 131 | S15: 33 | T15: 33 | U15: 60
A16: Jeudi | B16: 22 | C16: 71 | D16: 71 | E16: 72 | F16: 72 | G16: 72 | H16: 73 | I16: 73 | J16: 73 | K16: 74 | L16: 75 | M16: 75 | N16: 132 | O16: 135 | P16: 135 | Q16: 136 | R16: 137 | S16: 69 | T16: 70 | U16: 70
A17: Vendredi | B17: 21 | C17: 21 | D17: 21 | E17: 79 | F17: 79 | G17: 81 | H17: 83 | I17: 83 | J17: 86 | K17: 88 | L17: 88 | M17: 88 | N17: 138 | O17: 138 | P17: 139 | Q17: 140 | R17: 141 | S17: 76 | T17: 76 | U17: 85
A18: Samedi | B18: 93 | C18: 93 | D18: 107 | E18: 101 | F18: 101 | G18: 101 | H18: 103 | I18: 103 | J18: 103 | K18: 108 | L18: 108 | M18: 108 | N18: 143 | O18: 143 | P18: 144 | Q18: 144 | R18: 144 | S18: 87 | T18: 102 | U18: 102

Sheet TO G (2)
A1: ='TO G'!A1 -> 0 | B1: ='TO G'!B1 -> Laudes | F1: ='TO G'!F1 -> Vêpres | G1: ='TO G'!G1 -> Vêpres | H1: ='TO G'!H1 -> Vêpres | I1: ='TO G'!I1 -> Vêpres | J1: ='TO G'!J1 -> Vêpres | K1: ='TO G'!K1 -> Vêpres | L1: ='TO G'!L1 -> Vêpres | M1: ='TO G'!M1 -> Vêpres | ... AD1: ='TO G'!AD1 -> Complies
A2: ='TO G'!A2 -> 0 | B2: ='TO G'!B2 -> I | C2: ='TO G'!C2 -> II | D2: ='TO G'!D2 -> III | E2: ='TO G'!E2 -> IV | F2: ='TO G'!F2 -> I | H2: ='TO G'!H2 -> II | J2: ='TO G'!J2 -> III | L2: ='TO G'!L2 -> IV | N2: ='TO G'!N2 -> I | O2: ='TO G'!O2 -> V | P2: ='TO G'!P2 -> II | Q2: ='TO G'!Q2 -> VI | R2: ='TO G'!R2 -> III | S2: ='TO G'!S2 -> VII | T2: ='TO G'!T2 -> IV | U2: ='TO G'!U2 -> VIII | V2: ='TO G'!V2 -> I | X2: ='TO G'!X2 -> II | Z2: ='TO G'!Z2 -> III | AB2: ='TO G'!AB2 -> IV | AD2: ='TO G'!AD2 -> 0
A3: ='TO G'!A3 -> Dimanche | B3: ='TO G'!B3 -> 92 | G3: ='TO G'!G3 -> 0 | I3: ='TO G'!I3 -> 0 | K3: ='TO G'!K3 -> 0 | M3: ='TO G'!M3 -> 0 | V3: ='TO G'!V3 -> 117 | W3: ='TO G'!W3 -> 1-4 | X3: ='TO G'!X3 -> 22 | Y3: ='TO G'!Y3 -> 0 | Z3: ='TO G'!Z3 -> 117 | AA3: ='TO G'!AA3 -> 1-4 | AB3: ='TO G'!AB3 -> 22 | AC3: ='TO G'!AC3 -> 0 | AD3: ='TO G'!AD3 -> 90
B4: ='TO G'!B4 -> AT 49 | G4: ='TO G'!G4 -> 0 | I4: ='TO G'!I4 -> 0 | K4: ='TO G'!K4 -> 0 | M4: ='TO G'!M4 -> 0 | V4: ='TO G'!V4 -> 117 | W4: ='TO G'!W4 -> 5-24 | X4: ='TO G'!X4 -> 75 | Y4: ='TO G'!Y4 -> 2-7 | Z4: ='TO G'!Z4 -> 117 | AA4: ='TO G'!AA4 -> 5-24 | AB4: ='TO G'!AB4 -> 75 | AC4: ='TO G'!AC4 -> 2-7 | AD4: ='TO G'!AD4 -> 0
B5: ='TO G'!B5 -> 148 | G5: ='TO G'!G5 -> 0 | I5: ='TO G'!I5 -> 0 | K5: ='TO G'!K5 -> 0 | M5: ='TO G'!M5 -> 0 | V5: ='TO G'!V5 -> 117 | W5: ='TO G'!W5 -> 25-29 | X5: ='TO G'!X5 -> 75 | Y5: ='TO G'!Y5 -> 8-13 | Z5: ='TO G'!Z5 -> 117 | AA5: ='TO G'!AA5 -> 25-29 | AB5: ='TO G'!AB5 -> 75 | AC5: ='TO G'!AC5 -> 8-13 | AD5: ='TO G'!AD5 -> 0
A6: ='TO G'!A6 -> Lundi | B6: ='TO G'!B6 -> 5 | G6: ='TO G'!G6 -> 0 | I6: ='TO G'!I6 -> 0 | K6: ='TO G'!K6 -> 0 | M6: ='TO G'!M6 -> 0 | V6: ='TO G'!V6 -> 18B | W6: ='TO G'!W6 -> 0 | X6: ='TO G'!X6 -> 118 - VI | Y6: ='TO G'!Y6 -> 0 | Z6: ='TO G'!Z6 -> 118 - XI | AA6: ='TO G'!AA6 -> 0 | AB6: ='TO G'!AB6 -> 118 - XVII | AC6: ='TO G'!AC6 -> 0 | AD6: ='TO G'!AD6 -> 4
B7: ='TO G'!B7 -> AT 4 | G7: ='TO G'!G7 -> 0 | I7: ='TO G'!I7 -> 0 | K7: ='TO G'!K7 -> 0 | M7: ='TO G'!M7 -> 0 | V7: ='TO G'!V7 -> 7 | W7: ='TO G'!W7 -> 2-10 | X7: ='TO G'!X7 -> 39 | Y7: ='TO G'!Y7 -> 2-9 | Z7: ='TO G'!Z7 -> 70 | AA7: ='TO G'!AA7 -> 1-13 | AB7: ='TO G'!AB7 -> 81 | AC7: ='TO G'!AC7 -> 0 | AD7: ='TO G'!AD7 -> 133
B8: ='TO G'!B8 -> 91 | G8: ='TO G'!G8 -> 0 | I8: ='TO G'!I8 -> 0 | K8: ='TO G'!K8 -> 0 | M8: ='TO G'!M8 -> 0 | V8: ='TO G'!V8 -> 7 | W8: ='TO G'!W8 -> 11-18 | X8: ='TO G'!X8 -> 39 | Y8: ='TO G'!Y8 -> 10-18 | Z8: ='TO G'!Z8 -> 70 | AA8: ='TO G'!AA8 -> 14-24 | AB8: ='TO G'!AB8 -> 119 | AC8: ='TO G'!AC8 -> 0 | AD8: ='TO G'!AD8 -> 0
A9: ='TO G'!A9 -> Mardi | B9: ='TO G'!B9 -> 8 | G9: ='TO G'!G9 -> 0 | I9: ='TO G'!I9 -> 0 | K9: ='TO G'!K9 -> 0 | M9: ='TO G'!M9 -> 0 | V9: ='TO G'!V9 -> 118 - I | W9: ='TO G'!W9 -> 0 | X9: ='TO G'!X9 -> 118 - VII | Y9: ='TO G'!Y9 -> 0 | Z9: ='TO G'!Z9 -> 118 - XII | AA9: ='TO G'!AA9 -> 0 | AB9: ='TO G'!AB9 -> 118 - XVIII | AC9: ='TO G'!AC9 -> 0 | AD9: ='TO G'!AD9 -> 90
B10: ='TO G'!B10 -> AT 6 | G10: ='TO G'!G10 -> 0 | I10: ='TO G'!I10 -> 0 | K10: ='TO G'!K10 -> 0 | M10: ='TO G'!M10 -> 0 | V10: ='TO G'!V10 -> 11 | W10: ='TO G'!W10 -> 0 | X10: ='TO G'!X10 -> 48 | Y10: ='TO G'!Y10 -> 0 | Z10: ='TO G'!Z10 -> 73 | AA10: ='TO G'!AA10 -> 1-9 | AB10: ='TO G'!AB10 -> 87 | AC10: ='TO G'!AC10 -> 2-10a | AD10: ='TO G'!AD10 -> 0
B11: ='TO G'!B11 -> 95 | G11: ='TO G'!G11 -> 0 | I11: ='TO G'!I11 -> 0 | K11: ='TO G'!K11 -> 0 | M11: ='TO G'!M11 -> 0 | V11: ='TO G'!V11 -> 12 | W11: ='TO G'!W11 -> 0 | X11: ='TO G'!X11 -> 48 | Y11: ='TO G'!Y11 -> 0 | Z11: ='TO G'!Z11 -> 73 | AA11: ='TO G'!AA11 -> 10-23 | AB11: ='TO G'!AB11 -> 87 | AC11: ='TO G'!AC11 -> 10b-19 | AD11: ='TO G'!AD11 -> 0
A12: ='TO G'!A12 -> Mercredi | B12: ='TO G'!B12 -> 18A | G12: ='TO G'!G12 -> 0 | I12: ='TO G'!I12 -> 0 | K12: ='TO G'!K12 -> 0 | M12: ='TO G'!M12 -> 0 | V12: ='TO G'!V12 -> 118 - II | W12: ='TO G'!W12 -> 0 | X12: ='TO G'!X12 -> 118 - I | Y12: ='TO G'!Y12 -> 0 | Z12: ='TO G'!Z12 -> 118 - XIII | AA12: ='TO G'!AA12 -> 0 | AB12: ='TO G'!AB12 -> 118 - XIX | AC12: ='TO G'!AC12 -> 0 | AD12: ='TO G'!AD12 -> 4
B13: ='TO G'!B13 -> AT 8 | G13: ='TO G'!G13 -> 0 | I13: ='TO G'!I13 -> 0 | K13: ='TO G'!K13 -> 0 | M13: ='TO G'!M13 -> 0 | V13: ='TO G'!V13 -> 13 | W13: ='TO G'!W13 -> 0 | X13: ='TO G'!X13 -> 52 | Y13: ='TO G'!Y13 -> 0 | Z13: ='TO G'!Z13 -> 74 | AA13: ='TO G'!AA13 -> 0 | AB13: ='TO G'!AB13 -> 93 | AC13: ='TO G'!AC13 -> 1-11 | AD13: ='TO G'!AD13 -> 133
B14: ='TO G'!B14 -> 96 | G14: ='TO G'!G14 -> 0 | I14: ='TO G'!I14 -> 0 | K14: ='TO G'!K14 -> 0 | M14: ='TO G'!M14 -> 0 | V14: ='TO G'!V14 -> 14 | W14: ='TO G'!W14 -> 0 | X14: ='TO G'!X14 -> 53 | Y14: ='TO G'!Y14 -> 0 | Z14: ='TO G'!Z14 -> 76 | AA14: ='TO G'!AA14 -> 0 | AB14: ='TO G'!AB14 -> 93 | AC14: ='TO G'!AC14 -> 12-23 | AD14: ='TO G'!AD14 -> 0
A15: ='TO G'!A15 -> Jeudi | B15: ='TO G'!B15 -> 28 | G15: ='TO G'!G15 -> 0 | I15: ='TO G'!I15 -> 0 | K15: ='TO G'!K15 -> 1-10 | M15: ='TO G'!M15 -> 0 | V15: ='TO G'!V15 -> 118 - III | W15: ='TO G'!W15 -> 0 | X15: ='TO G'!X15 -> 118 - VIII | Y15: ='TO G'!Y15 -> 0 | Z15: ='TO G'!Z15 -> 118 - XIV | AA15: ='TO G'!AA15 -> 0 | AB15: ='TO G'!AB15 -> 118 - XX | AC15: ='TO G'!AC15 -> 0 | AD15: ='TO G'!AD15 -> 90
B16: ='TO G'!B16 -> AT 44 | G16: ='TO G'!G16 -> 0 | I16: ='TO G'!I16 -> 0 | K16: ='TO G'!K16 -> 11-18 | M16: ='TO G'!M16 -> 0 | V16: ='TO G'!V16 -> 41 | W16: ='TO G'!W16 -> 0 | X16: ='TO G'!X16 -> 54 | Y16: ='TO G'!Y16 -> 0 | Z16: ='TO G'!Z16 -> 80 | AA16: ='TO G'!AA16 -> 0 | AB16: ='TO G'!AB16 -> 127 | AC16: ='TO G'!AC16 -> 0 | AD16: ='TO G'!AD16 -> 0
B17: ='TO G'!B17 -> 97 | G17: ='TO G'!G17 -> 0 | I17: ='TO G'!I17 -> 0 | K17: ='TO G'!K17 -> 0 | M17: ='TO G'!M17 -> 0 | V17: ='TO G'!V17 -> 42 | W17: ='TO G'!W17 -> 0 | X17: ='TO G'!X17 -> 54 | Y17: ='TO G'!Y17 -> 0 | Z17: ='TO G'!Z17 -> 80 | AA17: ='TO G'!AA17 -> 0 | AB17: ='TO G'!AB17 -> 128 | AC17: ='TO G'!AC17 -> 0 | AD17: ='TO G'!AD17 -> 0
A18: ='TO G'!A18 -> Vendredi | B18: ='TO G'!B18 -> 50 | G18: ='TO G'!G18 -> 0 | I18: ='TO G'!I18 -> 0 | K18: ='TO G'!K18 -> 0 | M18: ='TO G'!M18 -> 0 | V18: ='TO G'!V18 -> 118 - IV | W18: ='TO G'!W18 -> 0 | X18: ='TO G'!X18 -> 118 - IX | Y18: ='TO G'!Y18 -> 0 | Z18: ='TO G'!Z18 -> 21 | AA18: ='TO G'!AA18 -> 2-11 | AB18: ='TO G'!AB18 -> 118 - XXI | AC18: ='TO G'!AC18 -> 0 | AD18: ='TO G'!AD18 -> 4
B19: ='TO G'!B19 -> AT 30 | G19: ='TO G'!G19 -> 0 | I19: ='TO G'!I19 -> 0 | K19: ='TO G'!K19 -> 0 | M19: ='TO G'!M19 -> 0 | V19: ='TO G'!V19 -> 25 | W19: ='TO G'!W19 -> 0 | X19: ='TO G'!X19 -> 55 | Y19: ='TO G'!Y19 -> 0 | Z19: ='TO G'!Z19 -> 21 | AA19: ='TO G'!AA19 -> 12-22 | AB19: ='TO G'!AB19 -> 132 | AC19: ='TO G'!AC19 -> 0 | AD19: ='TO G'!AD19 -> 133
B20: ='TO G'!B20 -> 98 | G20: ='TO G'!G20 -> 0 | I20: ='TO G'!I20 -> 0 | K20: ='TO G'!K20 -> 0 | M20: ='TO G'!M20 -> 0 | V20: ='TO G'!V20 -> 27 | W20: ='TO G'!W20 -> 0 | X20: ='TO G'!X20 -> 60 | Y20: ='TO G'!Y20 -> 0 | Z20: ='TO G'!Z20 -> 21 | AA20: ='TO G'!AA20 -> 23-32 | AB20: ='TO G'!AB20 -> 137 | AC20: ='TO G'!AC20 -> 0 | AD20: ='TO G'!AD20 -> 0
A21: ='TO G'!A21 -> Samedi | B21: ='TO G'!B21 -> 32 | G21: ='TO G'!G21 -> 2-10 | I21: ='TO G'!I21 -> 0 | K21: ='TO G'!K21 -> 0 | M21: ='TO G'!M21 -> 0 | V21: ='TO G'!V21 -> 118 - V | W21: ='TO G'!W21 -> 0 | X21: ='TO G'!X21 -> 118 - X | Y21: ='TO G'!Y21 -> 0 | Z21: ='TO G'!Z21 -> 118 - XV | AA21: ='TO G'!AA21 -> 0 | AB21: ='TO G'!AB21 -> 118 - XXII | AC21: ='TO G'!AC21 -> 0 | AD21: ='TO G'!AD21 -> 4
B22: ='TO G'!B22 -> AT 1 | G22: ='TO G'!G22 -> 11-18 | I22: ='TO G'!I22 -> 0 | K22: ='TO G'!K22 -> 0 | M22: ='TO G'!M22 -> 0 | V22: ='TO G'!V22 -> 33 | W22: ='TO G'!W22 -> 2-11 | X22: ='TO G'!X22 -> 61 | Y22: ='TO G'!Y22 -> 0 | Z22: ='TO G'!Z22 -> 33 | AA22: ='TO G'!AA22 -> 2-11 | AB22: ='TO G'!AB22 -> 44 | AC22: ='TO G'!AC22 -> 2-10 | AD22: ='TO G'!AD22 -> 133
B23: ='TO G'!B23 -> 99 | G23: ='TO G'!G23 -> 0 | I23: ='TO G'!I23 -> 0 | K23: ='TO G'!K23 -> 0 | M23: ='TO G'!M23 -> 0 | V23: ='TO G'!V23 -> 33 | W23: ='TO G'!W23 -> 12-23 | X23: ='TO G'!X23 -> 63 | Y23: ='TO G'!Y23 -> 0 | Z23: ='TO G'!Z23 -> 33 | AA23: ='TO G'!AA23 -> 12-23 | AB23: ='TO G'!AB23 -> 44 | AC23: ='TO G'!AC23 -> 11-18 | AD23: ='TO G'!AD23 -> 0
B24: ='TO G'!C3 -> 117
B25: ='TO G'!C4 -> AT 48
B26: ='TO G'!C5 -> 150 | E26: 62
B27: ='TO G'!C6 -> 35
B28: ='TO G'!C7 -> AT 15
B29: ='TO G'!C8 -> 112-116
B30: ='TO G'!C9 -> 45
B31: ='TO G'!C10 -> AT 25
B32: ='TO G'!C11 -> 134
B33: ='TO G'!C12 -> 46
B34: ='TO G'!C13 -> AT 3
B35: ='TO G'!C14 -> 145
B36: ='TO G'!C15 -> 47
B37: ='TO G'!C16 -> AT 20
B38: ='TO G'!C17 -> 146
... B44: ='TO G'!C23 -> 149
B45: ='TO G'!D3 -> 92
...

Sheet Feuil2
A1: Liste | B1: Psaumes
A2: 193 | B2: 0
A3: 194 | B3: 0
A4: 195 | B4: 0
A5: 196 | B5: 0
A6: 197 | B6: 0
A7: 198 | B7: 0
A8: 205 | B8: 0
A9: 206 | B9: 0
A10: 207 | B10: 0
A11: 208 | B11: 0
A12: 209 | B12: 0
A13: 210 | B13: 0
... A85: 342 | B85: 7
A86: 7 | B86: 8 | D86: 9
A87: 177 | B87: 10
A88: 344 | B88: 11
A89: 211 | B89: 12
A90: 345 | B90: 12
A91: 347 | B91: 13
A92: 348 | B92: 14
A93: 178 | B93: 15
A94: 212 | B94: 15
A95: 88 | B95: 16
A96: 89 | B96: 16
A97: 199 | B97: 17
A98: 200 | B98: 17
... A105: 255 | B105: 17
A106: 91 | B106: 19 | D106: 18
A107: 184 | B107: 19
A108: 92 | B108: 20
A109: 185 | B109: 20
A110: 394 | B110: 21
A111: 395 | B111: 21
A112: 396 | B112: 21
A113: 358 | B113: 22
A114: 400 | B114: 22
A115: 179 | B115: 23
A116: 213 | B116: 23
A117: 94 | B117: 24
...
